Workbook

Sheet Balance Sheet
A1: Hyundai
A5: Particulars | B5: 2021 | C5: 2022 | D5: 2023 | E5: 2024
A6: Assets
A7: Non-current assets
A8: Property, plant and equipment | B8: 62290.52 | C8: 57656.36 | D8: 67135.59 | E8: 62907.54
A9: Capital work in progress | B9: 5291.25 | C9: 13366.35 | D9: 6528.42 | E9: 47183.61
A10: Intangible assets | B10: 3758.62 | C10: 3270.32 | D10: 6183.42 | E10: 6192.5
A11: Right of use assets | B11: 662.96 | C11: 577.65 | D11: 2825.26 | E11: 1951.01
A12: Financial assets
A13: Other Financial assets | B13: 493.98 | C13: 516.97 | D13: 624.12 | E13: 774.01
A14: Deferred tax asset (net) | B14: 6156.74 | C14: 8265.99 | D14: 9477.9 | E14: 10320.99
A15: Non-current tax assets (net) | B15: 2081.53 | C15: 6146.71 | D15: 6886.39 | E15: 6465.27
A16: Other non current assets | B16: 2046.57 | C16: 2313.36 | D16: 2590.92 | E16: 4855.25
A17: Total non current assets | B17: =SUM(B8:B16) -> 82782.17 | C17: =SUM(C8:C16) -> 92113.71 | D17: =SUM(D8:D16) -> 102252.02 | E17: =SUM(E8:E16) -> 140650.18
A19: Current assets
A20: Inventories | B20: 28811.2 | C20: 34224.09 | D20: 33156.29 | E20: 34043.57
A21: Financial assets
A22: Trade receivables | B22: 21824.07 | C22: 28971.92 | D22: 25100.26 | E22: 23891.23
A23: Cash and cash equivalents | B23: 141388.42 | C23: 177411.47 | D23: 9732.15 | E23: 48457.17
A24: Bank balance other than above | D24: 80441.3 | E24: 37334.53
A25: Loans | B25: 154.94 | C25: 659.48
A26: Other Financial assets | B26: 3005.15 | C26: 4539.58 | D26: 3439.24 | E26: 4572.66
A27: Other current assets | B27: 5634.63 | C27: 7813.17 | D27: 9371.19 | E27: 12024.25
A28: Total curent assets | B28: =SUM(B20:B27) -> 200818.41 | C28: =SUM(C20:C27) -> 253619.71 | D28: =SUM(D20:D27) -> 161240.43 | E28: =SUM(E20:E27) -> 160323.41
A29: Total assets | B29: =B17+B28 -> 283600.58 | C29: =C17+C28 -> 345733.42 | D29: =D17+D28 -> 263492.45 | E29: =E17+E28 -> 300973.59
A31: Equity
A32: Equity share capital | B32: 8125.41 | C32: 8125.41 | D32: 8125.41 | E32: 8125.41
A33: Retained earnings | B33: 160437.14 | C33: 192422.77 | D33: 98531.16 | E33: 154839.24
A34: Total equity | B34: =SUM(B32:B33) -> 168562.55 | C34: =SUM(C32:C33) -> 200548.18 | D34: =SUM(D32:D33) -> 106656.57 | E34: =SUM(E32:E33) -> 162964.65
A36: Liabilities
A37: Non-current liabilities
A38: Financial liabilities
A39: Borrowings | B39: 7667.1 | C39: 7065.66 | D39: 6227.97 | E39: 5359.88
A40: Lease liabilities | B40: 307.47 | C40: 267.23 | D40: 557.68 | E40: 474.38
A41: Provisions | B41: 7743.02 | C41: 8037.65 | D41: 8467.39 | E41: 8736.37
A42: Other non-current liabilities | B42: 7378.07 | C42: 9759.55 | D42: 11610.97 | E42: 10775.08
A43: Total non current liabilities | B43: =SUM(B39:B42) -> 23095.66 | C43: =SUM(C39:C42) -> 25130.09 | D43: =SUM(D39:D42) -> 26864.01 | E43: =SUM(E39:E42) -> 25345.71
A45: Current liabilities
A46: Financial liabilities
A47: Borrowings | B47: 3733.23 | C47: 4520.34 | D47: 1451.18 | E47: 2558.37
...

Sheet P&L
A1: Hyundai
A5: Particulars | B5: 2021 | C5: 2022 | D5: 2023 | E5: 2024
A6: Income
A7: Revenue from operations / Revenue from operations | B7: 473784.32 | C7: 603075.8 | D7: 698290.57 | E7: 691928.88
A8: Other income | B8: 5876.16 | C8: 11290.62 | D8: 14732.68 | E8: 8700.49
A9: Total income | B9: =SUM(B7:B8) -> 479660.48 | C9: =SUM(C7:C8) -> 614366.42 | D9: =SUM(D7:D8) -> 713023.25 | E9: =SUM(E7:E8) -> 700629.37
A11: Expenses
A12: Cost of materials | B12: 352308.08 | C12: 445086.35 | D12: 512979.91 | E12: 493978.87
A13: Purchase of stock in trade | B13: 6564.05 | C13: 6564.16 | D13: 4334.27 | E13: 7407.41
A14: Work in progress | B14: -621.2 | C14: -1351.21 | D14: -1384.74 | E14: -1772.37
A15: Employee benefit expense | B15: 16476.38 | C15: 17662.26 | D15: 19754.88 | E15: 23112.09
A16: Finance cost | B16: 1319.13 | C16: 1424.01 | D16: 1580.79 | E16: 1272
A17: Depreciation and amortisation expense | B17: 21695.86 | C17: 21898.66 | D17: 22079.31 | E17: 21052.58
A18: Other expenses | B18: 44397.74 | C18: 60098.7 | D18: 71820.52 | E18: 79989.8
A19: Cost of vehicles for own use | B19: -201.61 | C19: -472.26 | D19: -540.43 | E19: -414.5
A20: EBITDA | B20: =B9-SUM(B12:B15,B17:B19) -> 39041.18 | C20: =C9-SUM(C12:C15,C17:C19) -> 64879.76 | D20: =D9-SUM(D12:D15,D17:D19) -> 83979.53 | E20: =E9-SUM(E12:E15,E17:E19) -> 77275.49
A21: Total Expenses | B21: =SUM(B12:B19) -> 441938.43 | C21: =SUM(C12:C19) -> 550910.67 | D21: =SUM(D12:D19) -> 630624.51 | E21: =SUM(E12:E19) -> 624625.88
A22: Profit Before Tax | B22: =B9-B21 -> 37722.05 | C22: =C9-C21 -> 63455.75 | D22: =D9-D21 -> 82398.74 | E22: =E9-E21 -> 76003.49
A24: Tax Expense
A25: Current tax | B25: 10377.87 | C25: 18414.53 | D25: 22965.26 | E25: 20322.83
A26: Defered tax (net) | B26: -1671.72 | C26: -2051.28 | D26: -1166.96 | E26: -811.48
A27: Total tax expense | B27: =SUM(B25:B26) -> 8706.15 | C27: =SUM(C25:C26) -> 16363.25 | D27: =SUM(D25:D26) -> 21798.3 | E27: =SUM(E25:E26) -> 19511.35
A28: Profit after tax | B28: =B22-B27 -> 29015.9 | C28: =C22-C27 -> 47092.5 | D28: =D22-D27 -> 60600.44 | E28: =E22-E27 -> 56492.14
A30: Effective tax rate | B30: =B27/B22 -> 0.23079737 | C30: =C27/C22 -> 0.25786867 | D30: =D27/D22 -> 0.26454652 | E30: =E27/E22 -> 0.2567165
A32: Operating profit | B32: =B7-B21 -> 31845.89 | C32: =C7-C21 -> 52165.13 | D32: =D7-D21 -> 67666.06 | E32: =E7-E21 -> 67303
A33: EBIT | B33: =B20-B17 -> 17345.32 | C33: =C20-C17 -> 42981.1 | D33: =D20-D17 -> 61900.22 | E33: =E20-E17 -> 56222.91

Sheet Ratios
A1: Hyundai
A5: Particulars | B5: Formulas | C5: 2021 | D5: 2022 | E5: 2023 | F5: 2024
A7: Profitability Ratios
A8: OPM | B8: Operating profit / Revenue from operations | C8: ='P&L'!B32/'P&L'!B7 -> 0.067216007 | D8: ='P&L'!C32/'P&L'!C7 -> 0.086498463 | E8: ='P&L'!D32/'P&L'!D7 -> 0.09690244 | F8: ='P&L'!E32/'P&L'!E7 -> 0.097268667
A9: EBIT margin | B9: EBIT / Total revenue | C9: ='P&L'!B33/'P&L'!B9 -> 0.036161662 | D9: ='P&L'!C33/'P&L'!C9 -> 0.069960041 | E9: ='P&L'!D33/'P&L'!D9 -> 0.086813747 | F9: ='P&L'!E33/'P&L'!E9 -> 0.080246293
A10: NPM | B10: Net profit / Total revenue | C10: ='P&L'!B28/'P&L'!B9 -> 0.06049258 | D10: ='P&L'!C28/'P&L'!C9 -> 0.076652139 | E10: ='P&L'!D28/'P&L'!D9 -> 0.084990833 | F10: ='P&L'!E28/'P&L'!E9 -> 0.080630562
A12: Return Ratios
A13: Return on equity | B13: NP / Equity | C13: ='P&L'!B28/'Balance Sheet'!B34 -> 0.17213729 | D13: ='P&L'!C28/'Balance Sheet'!C34 -> 0.23481888 | E13: ='P&L'!D28/'Balance Sheet'!D34 -> 0.56818291 | F13: ='P&L'!E28/'Balance Sheet'!E34 -> 0.34665272
A14: Return on capital emloyed | B14: EBIT / (Equity + Debt) | C14: ='P&L'!B33/('Balance Sheet'!B34+'Balance Sheet'!B47+'Balance Sheet'!B39) -> 0.096382765 | D14: ='P&L'!C33/('Balance Sheet'!C34+'Balance Sheet'!C47+'Balance Sheet'!C39) -> 0.2026128 | E14: ='P&L'!D33/('Balance Sheet'!D34+'Balance Sheet'!D47+'Balance Sheet'!D39) -> 0.54139004 | F14: ='P&L'!E33/('Balance Sheet'!E34+'Balance Sheet'!E47+'Balance Sheet'!E39) -> 0.32901425
A16: Debt ratios
A17: Debt / Equity | B17: Total borrowings / Equity | C17: =('Balance Sheet'!B39+'Balance Sheet'!B47)/'Balance Sheet'!B34 -> 0.067632638 | D17: =('Balance Sheet'!C39+'Balance Sheet'!C47)/'Balance Sheet'!C34 -> 0.057771654 | E17: =('Balance Sheet'!D39+'Balance Sheet'!D47)/'Balance Sheet'!D34 -> 0.071998846 | F17: =('Balance Sheet'!E39+'Balance Sheet'!E47)/'Balance Sheet'!E34 -> 0.048588758
A18: Interest coverage ratio | B18: EBIT / Finance costs | C18: ='P&L'!B33/'P&L'!B16 -> 13.14906 | D18: ='P&L'!C33/'P&L'!C16 -> 30.183145 | E18: ='P&L'!D33/'P&L'!D16 -> 39.157776 | F18: ='P&L'!E33/'P&L'!E16 -> 44.200401
A20: Turnover ratio
A21: Total asset turnover | B21: Sales / Total Assets | C21: ='P&L'!B7/'Balance Sheet'!B29 -> 1.6706042 | D21: ='P&L'!C7/'Balance Sheet'!C29 -> 1.7443376 | E21: ='P&L'!D7/'Balance Sheet'!D29 -> 2.650135 | F21: ='P&L'!E7/'Balance Sheet'!E29 -> 2.2989688
A22: Recieveable turnover | B22: Sales / Recieveable | C22: ='P&L'!B7/'Balance Sheet'!B22 -> 21.709256 | D22: ='P&L'!C7/'Balance Sheet'!C22 -> 20.815873 | E22: ='P&L'!D7/'Balance Sheet'!D22 -> 27.820053 | F22: ='P&L'!E7/'Balance Sheet'!E22 -> 28.961627
A23: Inventory turnover | B23: Sales / Inventory | C23: ='P&L'!B7/'Balance Sheet'!B20 -> 16.444449 | D23: ='P&L'!C7/'Balance Sheet'!C20 -> 17.621383 | E23: ='P&L'!D7/'Balance Sheet'!D20 -> 21.060576 | F23: ='P&L'!E7/'Balance Sheet'!E20 -> 20.324804
A24: Payable turnover | B24: Sales / Payable | C24: ='P&L'!B7/('Balance Sheet'!B50+'Balance Sheet'!B51) -> 8.7617315 | D24: ='P&L'!C7/('Balance Sheet'!C50+'Balance Sheet'!C51) -> 8.1049523 | E24: ='P&L'!D7/('Balance Sheet'!D50+'Balance Sheet'!D51) -> 9.319168 | F24: ='P&L'!E7/('Balance Sheet'!E50+'Balance Sheet'!E51) -> 9.764445
A27: Working capital (days sale outstanding)
A28: Recieveable days | B28: 365 / Revieveable turnover ratio | C28: =365/C22 -> 16.813105 | D28: =365/D22 -> 17.534696 | E28: =365/E22 -> 13.120032 | F28: =365/F22 -> 12.602883
A29: Inventory days | B29: 365 / Inventory turnover ratio | C29: =365/C23 -> 22.195939 | D29: =365/D23 -> 20.713471 | E29: =365/E23 -> 17.33096 | F29: =365/F23 -> 17.958353
A30: Payable Days | B30: 365 / Payable turnover ratio | C30: =365/C24 -> 41.658433 | D30: =365/D24 -> 45.034195 | E30: =365/E24 -> 39.166587 | F30: =365/F24 -> 37.380517
A32: Dupont analysis | B32: NPM * Asset turnover ratio * Leverage factor (Assets/Equity) | C32: =C10*C21*('Balance Sheet'!B29/'Balance Sheet'!B34) -> 0.17002849 | D32: =D10*D21*('Balance Sheet'!C29/'Balance Sheet'!C34) -> 0.23050346 | E32: =E10*E21*('Balance Sheet'!D29/'Balance Sheet'!D34) -> 0.55644296 | F32: =F10*F21*('Balance Sheet'!E29/'Balance Sheet'!E34) -> 0.34234795
A35: Cost Analysis | B35: Cost of materials | C35: ='P&L'!B12/'P&L'!B$7 -> 0.74360435 | D35: ='P&L'!C12/'P&L'!C$7 -> 0.73802721 | E35: ='P&L'!D12/'P&L'!D$7 -> 0.73462242 | F35: ='P&L'!E12/'P&L'!E$7 -> 0.71391567
B36: Purchase of stock in trade | C36: ='P&L'!B13/'P&L'!B$7 -> 0.013854511 | D36: ='P&L'!C13/'P&L'!C$7 -> 0.010884469 | E36: ='P&L'!D13/'P&L'!D$7 -> 0.006206972 | F36: ='P&L'!E13/'P&L'!E$7 -> 0.01070545
B37: Work in progress | C37: ='P&L'!B14/'P&L'!B$7 -> -0.0013111451 | D37: ='P&L'!C14/'P&L'!C$7 -> -0.002240531 | E37: ='P&L'!D14/'P&L'!D$7 -> -0.0019830427 | F37: ='P&L'!E14/'P&L'!E$7 -> -0.0025614916
B38: Employee benefit expense | C38: ='P&L'!B15/'P&L'!B$7 -> 0.034776119 | D38: ='P&L'!C15/'P&L'!C$7 -> 0.029286965 | E38: ='P&L'!D15/'P&L'!D$7 -> 0.028290343 | F38: ='P&L'!E15/'P&L'!E$7 -> 0.033402407
B39: Finance cost | C39: ='P&L'!B16/'P&L'!B$7 -> 0.0027842416 | D39: ='P&L'!C16/'P&L'!C$7 -> 0.0023612455 | E39: ='P&L'!D16/'P&L'!D$7 -> 0.0022637997 | F39: ='P&L'!E16/'P&L'!E$7 -> 0.0018383392
B40: Depreciation and amortisation expense | C40: ='P&L'!B17/'P&L'!B$7 -> 0.045792693 | D40: ='P&L'!C17/'P&L'!C$7 -> 0.036311621 | E40: ='P&L'!D17/'P&L'!D$7 -> 0.031619087 | F40: ='P&L'!E17/'P&L'!E$7 -> 0.03042593
B41: Other expenses | C41: ='P&L'!B18/'P&L'!B$7 -> 0.093708758 | D41: ='P&L'!C18/'P&L'!C$7 -> 0.099653642 | E41: ='P&L'!D18/'P&L'!D$7 -> 0.10285191 | F41: ='P&L'!E18/'P&L'!E$7 -> 0.11560408
B42: Cost of vehicles for own use | C42: ='P&L'!B19/'P&L'!B$7 -> -0.00042553118 | D42: ='P&L'!C19/'P&L'!C$7 -> -0.00078308564 | E42: ='P&L'!D19/'P&L'!D$7 -> -0.00077393283 | F42: ='P&L'!E19/'P&L'!E$7 -> -0.00059905001
